<?xml version="1.0"?>
<robot name="2wheels" xmlns:xacro="http://www.ros.org/wiki/xacro">
  
  <!-- Chassis link -->
  <link name="link_chassis">
    <!-- pose and inertial -->
    <pose>0 0 0 0 0 0</pose>
    <inertial>
      <mass value="2.5"/>
      <origin rpy="0 0 0" xyz="0.01 0 0.03"/>
      <inertia ixx="0.009" ixy="0" ixz="0" iyy="0.00747" iyz="0" izz="0.015023"/>
    </inertial>
    <!-- body -->
    <collision name="collision_chassis">
      <origin rpy=" 0 0 0" xyz="0.01 0 0.03"/>
      <geometry>
        <box size="0.18 0.2 0.06"/> <!-- ancho, largo, alto -->
      </geometry>
    </collision>
    <visual>
      <origin rpy="0 0 0.0" xyz="0.0 0 0.0"/>
      <geometry>
        <mesh filename="package://two_wheels_description/meshes/robotmodel.dae"/>
      </geometry>
      <material name="blue"/> <!-- This is only for Rviz visualization -->
    </visual>
  </link>
  
  <!-- caster front link -->
  <link name="caster_wheel">
    <inertial>
      <mass value="0.05"/>
      <origin rpy="0 0 0" xyz="0 0 0"/>
      <inertia ixx="0.000002" ixy="0" ixz="0" iyy="0.000002" iyz="0" izz="0.000002"/>
    </inertial>
    <collision name="caster_front_collision">
      <origin rpy=" 0 0 0" xyz="0.0 0 0"/>
      <geometry>
        <sphere radius="0.01"/>
      </geometry>
      <surface>
        <friction>
          <ode>
            <mu>0</mu>
            <mu2>0</mu2>
            <slip1>1.0</slip1>
            <slip2>1.0</slip2>
          </ode>
        </friction>
      </surface>
    </collision>
    <visual name="caster_front_visual">
      <origin rpy=" 0 0 0" xyz="0.0 0 0"/>
      <geometry>
        <sphere radius="0.0095"/>
      </geometry>
    </visual>
  </link>
  
  <!-- Joint between caster and chassis -->
  <joint name="joint_caster" type="fixed">
    <origin rpy="0 0 0" xyz="0.008 0.085 -0.015"/>
    <child link="caster_wheel"/>
    <parent link="link_chassis"/>
  </joint>

  <!-- Right wheel -->
  <link name="link_right_wheel">
    <inertial>
      <mass value="0.1"/>
      <origin rpy="0 0 0" xyz="0 0 0"/>
      <inertia ixx="0.000016458" ixy="0" ixz="0" iyy="0.000016458" iyz="0" izz="0.00003125"/>
    </inertial>
    <collision name="link_right_wheel_collision">
      <origin rpy="0 0 0" xyz="0 0 0"/>
      <geometry>
        <cylinder length="0.01" radius="0.025"/>
      </geometry>
    </collision>
    <visual name="link_right_wheel_visual">
      <origin rpy="0 0 0" xyz="0 0 0"/>
      <geometry>
        <cylinder length="0.001" radius="0.001"/>
      </geometry>
    </visual>
  </link>
  
  <!-- Joint between right wheel and chassis -->
  <joint name="joint_right_wheel" type="continuous">
    <origin rpy="0 1.570 0" xyz="0.11 -0.057 0.012"/>
    <child link="link_right_wheel"/>
    <parent link="link_chassis"/>
    <axis rpy="0 0 0" xyz="0 0 -1"/>
    <limit effort="10000" velocity="1000"/>
    <joint_properties damping="1.0" friction="1.0"/>
  </joint>
  
   <!-- Transmission joint_left_wheel -->
  <transmission name="right_wheel_transmission">
    <type>transmission_interface/SimpleTransmission</type>
    <joint name="joint_right_wheel">
      <hardwareInterface>hardware_interface/VelocityJointInterface</hardwareInterface>
    </joint>
    <actuator name="right_wheel_motor">
      <hardwareInterface>VelocityJointInterface</hardwareInterface>
      <mechanicalReduction>1</mechanicalReduction>
    </actuator>
  </transmission>
  
  <!-- LEFT wheel -->
  <link name="link_left_wheel">
    <inertial>
      <mass value="0.1"/>
      <origin rpy="0 0 0" xyz="0 0 0"/>
      <inertia ixx="0.000016458" ixy="0" ixz="0" iyy="0.000016458" iyz="0" izz="0.00003125"/>
    </inertial>
    <collision name="link_left_wheel_collision">
      <origin rpy="0 0 0" xyz="0 0 0"/>
      <geometry>
        <cylinder length="0.01" radius="0.025"/>
      </geometry>
    </collision>
    <visual name="link_left_wheel_visual">
      <origin rpy="0 0 0" xyz="0 0 0"/>
      <geometry>
        <cylinder length="0.001" radius="0.001"/>
      </geometry>
    </visual>
  </link>
  
  <!-- Joint between LEFT wheel and chassis -->
  <joint name="joint_left_wheel" type="continuous">
    <!-- Previous  xyz="-0.095 -0.055 0.01 -->
    <origin rpy="0 -1.570 0" xyz="-0.095 -0.057 0.012"/> <!-- PAY ATTENTION NEGATIVE 'y' -->
    <child link="link_left_wheel"/>
    <parent link="link_chassis"/>
    <axis rpy="0 0 0" xyz="0 0 1"/>
    <limit effort="10000" velocity="1000"/>
    <joint_properties damping="1.0" friction="1.0"/>
  </joint>
  
  <!-- Transmission joint_left_wheel -->
  <transmission name="left_wheel_transmission">
    <type>transmission_interface/SimpleTransmission</type>
    <joint name="joint_left_wheel">
      <hardwareInterface>hardware_interface/VelocityJointInterface</hardwareInterface>
    </joint>
    <actuator name="left_wheel_motor">
      <hardwareInterface>VelocityJointInterface</hardwareInterface>
      <mechanicalReduction>1</mechanicalReduction>
    </actuator>
  </transmission>


  <!-- laser link -->
  <link name="sensor_laser">
    <inertial>
      <origin xyz="0 0 0" rpy="0 0 0" />
      <mass value="0.25" />
      <inertia ixx="0.000208333" ixy="0" ixz="0" iyy="0.000208333" iyz="0" izz="0.0003125"/>
    </inertial>
    
    <visual>
      <origin xyz="0 0 0" rpy="0 0 0" />
      <geometry>
        <cylinder radius="0.05" length="0.05"/>
      </geometry>
      <material name="white" />
    </visual>
    
    <collision>
      <origin xyz="0 0 0" rpy="0 0 0"/>
      <geometry>
        <cylinder radius="0.05" length="0.05"/>
      </geometry>
    </collision>
  </link>

  <!-- joint to attach the laser to the chassis -->
  <joint name="joint_sensor_laser" type="fixed">
    <origin xyz="0.0 0 0.09" rpy="0 0 1.57"/>
    <parent link="link_chassis"/>
    <child link="sensor_laser"/>
  </joint>


    <!-- plugin for the laser -->
   <gazebo reference="sensor_laser">
    <sensor type="ray" name="head_hokuyo_sensor">
      <pose>0 0 0 0 0 0</pose>
      <visualize>false</visualize>
      <update_rate>20</update_rate>
      <ray>
        <scan>
          <horizontal>
            <samples>720</samples>
            <resolution>1</resolution>
            <min_angle>-1.570796</min_angle>
            <max_angle>1.570796</max_angle>
          </horizontal>
        </scan>
        <range>
          <min>0.10</min>
          <max>10.0</max>
          <resolution>0.01</resolution>
        </range>
        <noise>
          <type>gaussian</type>
          <mean>0.0</mean>
          <stddev>0.01</stddev>
        </noise>
      </ray>
      <plugin name="gazebo_ros_head_hokuyo_controller" filename="libgazebo_ros_laser.so">
        <topicName>/base_scan</topicName>
        <frameName>sensor_laser</frameName>
      </plugin>
    </sensor>
  </gazebo>
  <!-- ros_control Gazebo plugin -->
  <gazebo>
    <plugin name="gazebo_ros_control" filename="libgazebo_ros_control.so">
    </plugin>
  </gazebo>
   
</robot>
